Workbook
Name \Z: #REF!
Name \Z: #REF!
Name __?: #REF!
Name __??????: #REF!
Name ___?: #REF!
Name ___??????: #REF!
Name ____?: #REF!
Name ____??????: #REF!
Name ____cao1: #REF!
Name ____cao2: #REF!
Name ____cao3: #REF!
Name ____cao4: #REF!
Name ____cao5: #REF!
Name ____cao6: #REF!
Name ____dai1: #REF!
Name ____dai2: #REF!
Name ____dai3: #REF!
Name ____dai4: #REF!
Name ____dai5: #REF!
Name ____dai6: #REF!
Name ____dan1: #REF!
Name ____dan2: #REF!
Name ____ddn400: #REF!
Name ____ddn600: #REF!
Name ____lap1: #REF!
Name ____lap2: #REF!
Name ____MAC12: #REF!
Name ____MAC46: #REF!
Name ____NCL100: #REF!
Name ____NCL200: #REF!
Name ____NCL250: #REF!
Name ____nin190: #REF!
Name ____phi10: #REF!
Name ____phi12: #REF!
Name ____phi14: #REF!
Name ____phi16: #REF!
Name ____phi18: #REF!
Name ____phi20: #REF!
Name ____phi22: #REF!
Name ____phi25: #REF!
Name ____phi28: #REF!
Name ____phi6: #REF!
Name ____phi8: #REF!
Name ____SN3: #REF!
Name ____TB1: #REF!
Name ____TL1: #REF!
Name ____TL2: #REF!
Name ____TL3: #REF!
Name ____TLA120: #REF!
Name ____TLA35: #REF!
Name ____TLA50: #REF!
Name ____TLA70: #REF!
Name ____TLA95: #REF!
Name ____VL100: #REF!
Name ____VL200: #REF!
Name ____VL250: #REF!
Name ___cao1: #REF!
Name ___cao2: #REF!
Name ___cao3: #REF!
Name ___cao4: #REF!

Sheet KQHDKD
A1: =CDPS!A1 -> 公司名/Tên CSKD: CÔNG TY TNHH NGẠN CHÂU
A2: =CDPS!A2 -> 地址/Địa Chỉ : 30KL, Tổ 1, Khu phố Khánh Long, Phường Tân Khánh, TP Hồ Chí Minh, Việt Nam
A3: =CDPS!A3 -> 税号/Mã số thuế: 3702307012
A5: BÁO CÁO KẾT QUẢ HOẠT ĐỘNG SẢN XUẤT KINH DOANH 损益表
A6: (Ban hành theo Thông tư số 200/2014/TT-BTC Ngày 22/12/2014 của Bộ BTC)
A7: =CDKT!A6 -> (Từ 01/01/2025 Đến 31/01/2025)
F8: Đơn vị tiền: VNĐ
A9: STT | B9: Tên chỉ tiêu 摘要名稱 | C9: Tên chỉ tiêu tiếng Hoa 中文摘要名稱 | D9: Mã | E9: Thuyết minh | F9: NĂM 2025年 | G9: NĂM 2024年
A10: -1 | B10: -2 | C10: -3 | D10: -4 | E10: -5 | F10: -6 | G10: -7
A11: 1 | B11: Doanh thu bán hàng và cung cấp dịch vụ | C11: 1. 銷貨及提供勞務營收 | D11: 01 | E11: 18. | F11: 5951365361 | G11: 8087186237
A12: 2 | B12: Các khoản giảm trừ doanh thu | C12: 2. 各項扣減帳款 | D12: 02
A13: 3 | B13: Doanh thu thuần về bán hàng và cung cấp dịch vụ (10 = 01 - 02) | C13: 3. 銷貨及提供勞務淨額 (10 = 01 - 02) | D13: 10 | F13: 5951365361 | G13: 8087186237
A14: 4 | B14: Giá vốn hàng bán | C14: 4. 銷貨成本 | D14: 11 | E14: 19. | F14: 5913632751 | G14: 7712329356
A15: 5 | B15: Lợi nhuận gộp về bán hàng và cung cấp dịch vụ (20 = 10 - 11) | C15: 5. 銷貨及提供勞務毛利 (20 = 10 - 11) | D15: 20 | F15: 37732610 | G15: 374856881
A16: 6 | B16: Doanh thu hoạt động tài chính | C16: 6. 非營業收益 | D16: 21 | E16: 20. | F16: 2779695 | G16: 3893447
A17: 7 | B17: Chi phí tài chính | C17: 7. 非營業費用 | D17: 22 | E17: 21. | F17: 31932647 | G17: 383058272
B18: - Trong đó: Chi phí lãi vay | C18: - 其中：利息費用 | D18: 23 | F18: 0 | G18: 161194679
A19: 8 | B19: Chi phí bán hàng | C19: 8. 銷貨費用 | D19: 25 | E19: 22. | F19: 33711035 | G19: 48211218
A20: 9 | B20: Chi phí quản lý doanh nghiệp | C20: 9. 營業管理費用 | D20: 26 | E20: 23. | F20: 1.270792e+09 | G20: 1609567641
A21: 10 | B21: Lợi nhuận thuần từ hoạt động kinh doanh (30 = 20 + (21 - 22) - (24 + 25)) | C21: 10. 營業利潤[30=20+(21-22)-(24+25)] | D21: 30 | F21: -1.2959234e+09 | G21: -1662086803
A22: 11 | B22: Thu nhập khác | C22: 11. 其他收益 | D22: 31 | E22: 24. | F22: 1451751 | G22: 47604542
A23: 12 | B23: Chi phí khác | C23: 12. 其他費用 | D23: 32 | E23: 25. | F23: 1605130403 | G23: 27676
A24: 13 | B24: Lợi nhuận khác (40 = 31 - 32) | C24: 13. 其他利潤 (40 = 31 - 32) | D24: 40 | F24: -1603678652 | G24: 47576866
A25: 14 | B25: Tổng lợi nhuận kế toán trước thuế (50 = 30 + 40) | C25: 14. 稅前總利潤(50 = 30 + 40) | D25: 50 | F25: -2.899602e+09 | G25: -1614509937
A26: 15 | B26: Chi phí thuế thu nhập doanh nghiệp hiện hành | C26: 15. 現行企業營所稅費用 | D26: 51 | E26: 26.
A27: 16 | B27: Chi phí thuế thu nhập doanh nghiệp hoãn lại | C27: 16. 遞延企業營所稅費用 | D27: 52
A28: 17 | B28: Lợi nhuận sau thuế thu nhập doanh nghiệp (60 = 50 - 51 - 52) | C28: 17. 稅後利潤 (60=50-51-52) | D28: 60 | F28: -2.899602e+09 | G28: -1614509937
A29: 18 | B29: Lãi cơ bản trên cổ phiếu (*) | D29: 70
A30: 19 | B30: Lãi suy giảm trên cổ phiếu (*) | D30: 71
D32: BD, ngày 31 tháng 01 năm 2025
A33: Người lập biểu | E33: Giám Đốc
E37: HSIEH, YAO-YI

Sheet CDKT
A1: =CDPS!A1 -> 公司名/Tên CSKD: CÔNG TY TNHH NGẠN CHÂU
A2: =CDPS!A2 -> 地址/Địa Chỉ : 30KL, Tổ 1, Khu phố Khánh Long, Phường Tân Khánh, TP Hồ Chí Minh, Việt Nam
A3: =CDPS!A3 -> 税号/Mã số thuế: 3702307012
A4: BẢNG CÂN ĐỐI KẾ TOÁN -资产负债表
A5: (Ban hành theo thông tư 200/2014/TT-BTC ngày 22/12/2014 của bộ trưởng BTC)
A6: (Từ 01/01/2025 Đến 31/01/2025)
F7: Đơn vị tiền: VNĐ
A8: STT | B8: Tên chỉ tiêu 摘要名稱 | C8: Tên chỉ tiêu tiếng Hoa 中文摘要名稱 | D8: Mã số 編號 | E8: Thuyết minh 說明 | F8: NĂM 2025年 | G8: NĂM 2024年
A9: -1 | B9: -2 | C9: -3 | D9: -4 | E9: -5 | F9: -6 | G9: -7
B10: TÀI SẢN | C10: 資產
A11: A | B11: A - TÀI SẢN NGẮN HẠN (100=110+120+130+140+150) | C11: A. 短期資產(100=110+120+130+140+150) | D11: 100 | F11: 3519687206 | G11: 6956519842 | H11: x
A12: I | B12: I. Tiền và các khoản tương đương tiền (110=111+112) | C12: I. 現金及各約當現金 | D12: 110 | E12: 5. | F12: 1991633255 | G12: 2837155407 | H12: x
A13: 1 | B13: 1. Tiền | C13: 1. 現金 | D13: 111 | F13: 1991633255 | G13: 2837155407 | H13: x
A14: 2 | B14: 2. Các khoản tương đương tiền | C14: 2. 各約當現金 | D14: 112 | G14: 0
A15: II | B15: II. Các khoản đầu tư tài chính ngắn hạn (120=121+129) | C15: II. 短期金融投資 | D15: 120 | F15: 0 | G15: 0
A16: 1 | B16: 1. Chứng khoán kinh doanh | C16: 1. 證券投資 | D16: 121
A17: 2 | B17: 2. Dự phòng giảm giá đầu tư ngắn hạn | C17: 2. 短期投資跌價損失備抵 | D17: 122
A18: 3 | B18: 3. Đầu tư nắm giữ đến ngày đáo hạn | C18: 3.短期到期性投資 | D18: 123
A19: III | B19: III. Các khoản phải thu ngắn hạn (130 = 131 + 132 + 133 + 134 + 135 + 139) | C19: III. 短期應收 | D19: 130 | F19: 1443322235 | G19: 2073224734 | H19: x
A20: 1 | B20: 1. Phải thu khách hàng | C20: 1. 應收帳款 | D20: 131 | E20: 6a. | F20: 5209726965 | G20: 5839629464 | H20: x
A21: 2 | B21: 2. Trả trước cho người bán | C21: 2. 預付貨款 | D21: 132 | G21: 0 | H21: x
A22: 3 | B22: 3. Phải thu nội bộ ngắn hạn | C22: 3. 短期應收內部 | D22: 133
A23: 4 | B23: 4. Phải thu theo tiến độ HĐXD | C23: 4. 依據營造合約進度收款 | D23: 134
A24: 5 | B24: 5. Phải thu về cho vay ngắn hạn | C24: 5. 應收短期借款 | D24: 135
A25: 6 | B25: 6. Các khoản phải thu khác | C25: 6. 其他短期應收款 | D25: 136 | F25: 0 | G25: 0
A26: 7 | B26: 7. Dự phòng phải thu ngắn hạn khó đòi | C26: 7. 待處理資產 | D26: 137 | E26: 7. | F26: -3766404730 | G26: -3766404730 | H26: x
A27: 8 | B27: 8. Tài sản thiếu chờ xử lý | C27: 8. 備抵呆帳 | D27: 139
A28: IV | B28: IV. Hàng tồn kho (140 = 141 + 149) | C28: IV. 庫存 | D28: 140 | F28: 0 | G28: 1863554838 | H28: x
A29: 1 | B29: 1. Hàng tồn kho | C29: 1. 庫存貨 | D29: 141 | E29: 8. | F29: 0 | G29: 1863554838 | H29: x
A30: 2 | B30: 2. Dự phòng giảm giá hàng tồn kho | C30: 2. 庫存貨跌價損失備抵 | D30: 149 | F30: 0 | G30: 0
A31: V | B31: V. Tài sản ngắn hạn khác (150 = 151 + 152 + 153 + 154 + 155) | C31: V. 其他短期資產 | D31: 150 | F31: 84731716 | G31: 182584863 | H31: x
A32: 1 | B32: 1. Chi phí trả trước ngắn hạn | C32: 短期預付款 | D32: 151 | E32: 9a. | F32: 16727359 | G32: 114580506 | H32: x
A33: 2 | B33: 2. Thuế GTGT được khấu trừ | C33: 進項增值稅 | D33: 152 | E33: 11. | F33: 0 | G33: 0
A34: 3 | B34: 3. Thuế và các khoản khác phải thu Nhà nước | C34: 應收國家稅款及其他帳款 | D34: 153 | E34: 12. | F34: 68004357 | G34: 68004357 | H34: x
A35: 4 | B35: 4. Giao dịch mua bán lại trái phiếu Chính phủ | C35: 政府債券交易 | D35: 154
A36: 5 | B36: 5. Tài sản ngắn hạn khác | C36: 其他短期資產 | D36: 155
A37: B | B37: B - TÀI SẢN DÀI HẠN (200=210+220+240+250+260) | C37: B. 長期資產 (200=210+220+240+250+260) | D37: 200 | F37: 1180725012 | G37: 1610698456 | H37: x
A38: I | B38: I- Các khoản phải thu dài hạn (210 = 211 + 212 + 213 + 214 + 215 +216 + 219) | C38: I. 長期應收 | D38: 210 | F38: 0 | G38: 0
A39: 1 | B39: 1. Phải thu dài hạn của khách hàng | C39: 1. 長期應收 | D39: 211
A40: 2 | B40: 2. Trả trước cho người bán dài hạn | C40: 長期預付貨款 | D40: 212 | F40: 0
...

Sheet CDPS
A1: 公司名/Tên CSKD: CÔNG TY TNHH NGẠN CHÂU
A2: 地址/Địa Chỉ : 30KL, Tổ 1, Khu phố Khánh Long, Phường Tân Khánh, TP Hồ Chí Minh, Việt Nam
A3: 税号/Mã số thuế: 3702307012
A4: BẢNG CÂN ĐỐI TÀI KHOẢN 试算表
A5: =#REF! -> #REF!
A7: MÃ TK | B7: Tên tài khoản tiếng Hoa 中文账户名 | C7: TÊN TÀI KHOẢN | D7: Số dư đầu kỳ 期初值 | H7: Số phát sinh trong kỳ 本期發生 | L7: Số dư cuối kỳ 期末值
D8: Nợ VND 借方 | E8: Nợ USD 借方 | F8: Có VND 貸方 | G8: Có USD 貸方 | H8: Nợ VND 借方 | I8: Nợ USD 借方 | J8: Có VND 貸方 | K8: Có USD 貸方 | L8: Nợ VND 借方 | M8: Nợ USD 借方 | N8: Có VND 貸方 | O8: Có USD 貸方
A9: 1111 | B9: 現金 越盾 | C9: Tiền Việt Nam | D9: 592112098 | E9: 0 | F9: 0 | G9: 0 | H9: 1950000000 | I9: 0 | J9: 2226593842 | K9: 0 | L9: 315518256 | M9: 0 | N9: 0 | O9: 0
A10: 112704 | B10: 1121AGR | C10: Tiền gửi NH Agribank - VND 5500201022704 | D10: 165054122 | E10: 0 | F10: 0 | G10: 0 | H10: 259100 | I10: 0 | J10: 79001551 | K10: 0 | L10: 86311671 | M10: 0 | N10: 0 | O10: 0
A11: 112551 | B11: 1121IVB | C11: Tiền gửi NH IVB -VND 5044255-001 | D11: 1973206995 | E11: 0 | F11: 0 | G11: 0 | H11: 7657854800 | I11: 0 | J11: 8148040659 | K11: 0 | L11: 1483021136 | M11: 0 | N11: 0 | O11: 0
A12: 112552 | B12: 1122IVB002 | C12: Tiền gửi NH IVB - USD 5044255-002 | D12: 106759928 | E12: 4219.76 | F12: 0 | G12: 0 | H12: 0 | I12: 0 | J12: 0 | K12: 0 | L12: 106759928 | M12: 4219.76 | N12: 0 | O12: 0
A13: 112553 | B13: 1122IVB003 | C13: Tiền gửi NH IVB - USD 5044255-003 | D13: 22264 | E13: 0.88 | F13: 0 | G13: 0 | H13: 0 | I13: 0 | J13: 0 | K13: 0 | L13: 22264 | M13: 0.88 | N13: 0 | O13: 0
A14: 131ARTCRE | C14: CTY TNHH INTERNATIONAL ART CREATION | H14: 4064029 | I14: 0 | J14: 4064029 | K14: 0 | L14: 0 | M14: 0 | N14: 0 | O14: 0
A15: 131KIET | C15: CTY CP CHẤN KIỆT | D15: 13771296 | E15: 0 | F15: 0 | G15: 0 | H15: 21054298 | I15: 0 | J15: 34825594 | K15: 0 | L15: 0 | M15: 0 | N15: 0 | O15: 0
A16: 131THINH | C16: CTY TNHH CƯỜNG THỊNH | H16: 0 | I16: 0 | J16: 0 | K16: 0 | L16: 0 | M16: 0 | N16: 0 | O16: 0
A17: 131ICH | C17: CTY TNHH ĐỒ GỖ DANH ÍCH | D17: 168245139 | E17: 0 | F17: 0 | G17: 0 | H17: 651138736 | I17: 0 | J17: 789534348 | K17: 0 | L17: 29849527 | M17: 0 | N17: 0 | O17: 0
A18: 131DG | C18: CTY TNHH ĐỒ GỖ GIA DỤNG DINH GIA VN | H18: 2063880 | I18: 0 | J18: 2063880 | K18: 0 | L18: 0 | M18: 0 | N18: 0 | O18: 0
A19: 131GCKL | C19: CTY TNHH MTV GỖ GIA CÔNG KIM LỰC | D19: 170003075 | E19: 0 | F19: 0 | G19: 0 | H19: 1385120071 | I19: 0 | J19: 1309186209 | K19: 0 | L19: 245936937 | M19: 0 | N19: 0 | O19: 0
A20: 131NGHIA | C20: CTY TNHH GỖ HẰNG NGHĨA | D20: 49429129 | E20: 0 | F20: 0 | G20: 0 | H20: 250697108 | I20: 0 | J20: 300126237 | K20: 0 | L20: 0 | M20: 0 | N20: 0 | O20: 0
A21: 131HOME | C21: CTY TNHH ESLITE HOME | D21: 139968607 | E21: 0 | F21: 0 | G21: 0 | H21: 0 | I21: 0 | J21: 29976000 | K21: 0 | L21: 109992607 | M21: 0 | N21: 0 | O21: 0
A22: 131HSINYA | C22: CTY TNHH CÔNG NGHIỆP GỖ HSIN YA | D22: 1531238 | E22: 0 | F22: 0 | G22: 0 | H22: 38102236 | I22: 0 | J22: 37738112 | K22: 0 | L22: 1895362 | M22: 0 | N22: 0 | O22: 0
A23: 131HUAXIN | C23: CTY TNHH DING XIN INDUSTRIAL (CTY TNHH HUA XIN CŨ) | D23: 366983560 | E23: 0 | F23: 0 | G23: 0 | H23: 48184416 | I23: 0 | J23: 74477232 | K23: 0 | L23: 340690744 | M23: 0 | N23: 0 | O23: 0
A24: 131JING | C24: CTY JING TZUAN FURNITURE CO.,LTD | D24: 227718338 | E24: 0 | F24: 0 | G24: 0 | H24: 0 | I24: 0 | J24: 0 | K24: 0 | L24: 227718338 | M24: 0 | N24: 0 | O24: 0
A25: 131PHONG | C25: CTY TNHH KIM PHONG | H25: 14271811 | I25: 0 | J25: 14271811 | K25: 0 | L25: 0 | M25: 0 | N25: 0 | O25: 0
A26: 131HAO | C26: CTY TNHH LONG HAO | D26: 18006428 | E26: 0 | F26: 0 | G26: 0 | H26: 0 | I26: 0 | J26: 0 | K26: 0 | L26: 18006428 | M26: 0 | N26: 0 | O26: 0
A27: 131LODE | C27: CTY TNHH LODE STAR | H27: 573810620 | I27: 0 | J27: 332061260 | K27: 0 | L27: 241749360 | M27: 0 | N27: 0 | O27: 0
A28: 131LT | C28: CTY TNHH MTV SX TM LÂM THỊNH | D28: 670729421 | E28: 0 | F28: 0 | G28: 0 | H28: 310974606 | I28: 0 | J28: 789481793 | K28: 0 | L28: 192222234 | M28: 0 | N28: 0 | O28: 0
A29: 131FURN | C29: CTY TNHH MAEVE FURN | D29: 0 | E29: 0 | F29: 0 | G29: 0 | H29: 9293324 | I29: 0 | J29: 8201520 | K29: 0 | L29: 1091804 | M29: 0 | N29: 0 | O29: 0
A30: 131TIEN | C30: CTY CP SX KD XNK MINH TIẾN | H30: 15631704 | I30: 0 | J30: 15631704 | K30: 0 | L30: 0 | M30: 0 | N30: 0 | O30: 0
A31: 131MS | C31: CTY TNHH MORI SHIGE | D31: 0 | E31: 0 | F31: 0 | G31: 0 | H31: 4606896 | I31: 0 | J31: 4606896 | K31: 0 | L31: 0 | M31: 0 | N31: 0 | O31: 0
A32: 131KY | C32: CTY TNHH NGHĨA KỲ | D32: 210935031 | E32: 0 | F32: 0 | G32: 0 | H32: 1604659328 | I32: 0 | J32: 1580510534 | K32: 0 | L32: 235083825 | M32: 0 | N32: 0 | O32: 0
A33: 131PDINH | C33: CTY TNHH NỘI THẤT GỖ PHÚ ĐỈNH | D33: 252504 | E33: 0 | F33: 0 | G33: 0 | H33: 2444818 | I33: 0 | J33: 2697322 | K33: 0 | L33: 0 | M33: 0 | N33: 0 | O33: 0
A34: 131HUAT | C34: CTY CP POH HUAT VN | D34: 4503168 | E34: 0 | F34: 0 | G34: 0 | H34: 21258720 | I34: 0 | J34: 20670984 | K34: 0 | L34: 5090904 | M34: 0 | N34: 0 | O34: 0
A35: 131SFA | C35: CTY TNHH SAN FA VN | D35: 6123600 | E35: 0 | F35: 0 | G35: 0 | H35: 18263092 | I35: 0 | J35: 24386692 | K35: 0 | L35: 0 | M35: 0 | N35: 0 | O35: 0
A36: 131SNGHE | C36: CTYTNHH SIÊU NGHỆ | D36: 821584069 | E36: 0 | F36: 0 | G36: 0 | H36: 0 | I36: 0 | J36: 0 | K36: 0 | L36: 821584069 | M36: 0 | N36: 0 | O36: 0
A37: 131THP | C37: CTY TNHH TM TAM HỢP PHÁT | D37: 1699946400 | E37: 0 | F37: 0 | G37: 0 | H37: 0 | I37: 0 | J37: 0 | K37: 0 | L37: 1699946400 | M37: 0 | N37: 0 | O37: 0
A38: 131TL | C38: CTY TNHH MTV THẮNG LÂM | D38: 387033948 | E38: 0 | F38: 0 | G38: 0 | H38: 0 | I38: 0 | J38: 0 | K38: 0 | L38: 387033948 | M38: 0 | N38: 0 | O38: 0
A39: 131TMBH | C39: CTY TNHH SX TM B H | D39: 57601406 | E39: 0 | F39: 0 | G39: 0 | H39: 0 | I39: 0 | J39: 0 | K39: 0 | L39: 57601406 | M39: 0 | N39: 0 | O39: 0
A40: 131TPP | C40: CTY TNHH THÀNH PHÚ PHÁT | D40: 39142810 | E40: 0 | F40: 0 | G40: 0 | H40: 755361294 | I40: 0 | J40: 794504104 | K40: 0 | L40: 0 | M40: 0 | N40: 0 | O40: 0
A41: 131TRDUC | C41: CTY CỔ PHẦN TRẦN ĐỨC | D41: 471056275 | E41: 0 | F41: 0 | G41: 0 | H41: 0 | I41: 0 | J41: 200000000 | K41: 0 | L41: 271056275 | M41: 0 | N41: 0 | O41: 0
...

Sheet 2293
C1: 44196 | D1: =SUBTOTAL(9,D5:D211) -> 13579452926 | F1: =SUM(F5:F211) -> 6866289494 | G1: =SUM(G5:G211) -> 865623692 | H1: =SUM(H5:H211) -> 4621022128 | I1: =SUM(I5:I211) -> 438479589 | J1: =SUM(J5:J211) -> 788038023 | K1: =SUM(K5:K211) -> 3.6651719e+09 | L1: trích lập của KT năm 2020
A2: Tên khách hàng | B2: Số Hóa đơn | C2: Ngày Hóa đơn | D2: Số tiền | E2: Phân tích tuổi nợ | K2: Tổng trích lập dự phòng
E3: Quá hạn (tháng) | F3: Quá hạn dưới 6 tháng | G3: 6 tháng - 1 năm | H3: 1 năm - 2 năm | I3: 2 năm - 3 năm | J3: từ 3 năm trở lên
F4: 0 | G4: 0.3 | H4: 0.5 | I4: 0.7 | J4: 1
A5: Phải thu - Công Ty TNHH Hua Xin | B5: 0000267 | C5: 43832 | D5: 18179700 | E5: =($C$1-C5)/30 -> 12.133333 | F5: =IF(E5<6,D5,0) -> 0 | G5: =IF(AND(E5>=6,E5<12),D5,0) -> 0 | H5: =IF(AND(E5>=12,E5<24),D5,0) -> 18179700 | I5: =IF(AND(E5>=24,E5<36),D5,0) -> 0 | J5: =IF(E5>=36,D5,0) -> 0 | K5: =F5*$F$4+G5*$G$4+H5*$H$4+I5*$I$4+J5*$J$4 -> 9089850
A6: Phải thu - Công Ty TNHH Hua Xin | B6: 0000267 | C6: 43832 | D6: 1817970 | E6: =($C$1-C6)/30 -> 12.133333 | F6: =IF(E6<6,D6,0) -> 0 | G6: =IF(AND(E6>=6,E6<12),D6,0) -> 0 | H6: =IF(AND(E6>=12,E6<24),D6,0) -> 1817970 | I6: =IF(AND(E6>=24,E6<36),D6,0) -> 0 | J6: =IF(E6>=36,D6,0) -> 0 | K6: =F6*$F$4+G6*$G$4+H6*$H$4+I6*$I$4+J6*$J$4 -> 908985
A7: Phải thu - Công Ty TNHH Hua Xin | B7: 0000307 | C7: 43887 | D7: 47676330 | E7: =($C$1-C7)/30 -> 10.3 | F7: =IF(E7<6,D7,0) -> 0 | G7: =IF(AND(E7>=6,E7<12),D7,0) -> 47676330 | H7: =IF(AND(E7>=12,E7<24),D7,0) -> 0 | I7: =IF(AND(E7>=24,E7<36),D7,0) -> 0 | J7: =IF(E7>=36,D7,0) -> 0 | K7: =F7*$F$4+G7*$G$4+H7*$H$4+I7*$I$4+J7*$J$4 -> 14302899
A8: Phải thu - Công Ty TNHH Hua Xin | B8: 0000307 | C8: 43887 | D8: 4767633 | E8: =($C$1-C8)/30 -> 10.3 | F8: =IF(E8<6,D8,0) -> 0 | G8: =IF(AND(E8>=6,E8<12),D8,0) -> 4767633 | H8: =IF(AND(E8>=12,E8<24),D8,0) -> 0 | I8: =IF(AND(E8>=24,E8<36),D8,0) -> 0 | J8: =IF(E8>=36,D8,0) -> 0 | K8: =F8*$F$4+G8*$G$4+H8*$H$4+I8*$I$4+J8*$J$4 -> 1430289.9
A9: Phải thu - Công Ty TNHH Hua Xin | B9: 0000355 | C9: 43917 | D9: 89319600 | E9: =($C$1-C9)/30 -> 9.3 | F9: =IF(E9<6,D9,0) -> 0 | G9: =IF(AND(E9>=6,E9<12),D9,0) -> 89319600 | H9: =IF(AND(E9>=12,E9<24),D9,0) -> 0 | I9: =IF(AND(E9>=24,E9<36),D9,0) -> 0 | J9: =IF(E9>=36,D9,0) -> 0 | K9: =F9*$F$4+G9*$G$4+H9*$H$4+I9*$I$4+J9*$J$4 -> 26795880
A10: Phải thu - Công Ty TNHH Hua Xin | B10: 0000355 | C10: 43917 | D10: 8931960 | E10: =($C$1-C10)/30 -> 9.3 | F10: =IF(E10<6,D10,0) -> 0 | G10: =IF(AND(E10>=6,E10<12),D10,0) -> 8931960 | H10: =IF(AND(E10>=12,E10<24),D10,0) -> 0 | I10: =IF(AND(E10>=24,E10<36),D10,0) -> 0 | J10: =IF(E10>=36,D10,0) -> 0 | K10: =F10*$F$4+G10*$G$4+H10*$H$4+I10*$I$4+J10*$J$4 -> 2679588
A11: Phải thu - Công Ty TNHH Hua Xin | B11: 785 | C11: 43479 | D11: 3731440 | E11: =($C$1-C11)/30 -> 23.9 | F11: =IF(E11<6,D11,0) -> 0 | G11: =IF(AND(E11>=6,E11<12),D11,0) -> 0 | H11: =IF(AND(E11>=12,E11<24),D11,0) -> 3731440 | I11: =IF(AND(E11>=24,E11<36),D11,0) -> 0 | J11: =IF(E11>=36,D11,0) -> 0 | K11: =F11*$F$4+G11*$G$4+H11*$H$4+I11*$I$4+J11*$J$4 -> 1865720
A12: Phải thu - Công Ty TNHH Hua Xin | B12: 785 | C12: 43479 | D12: 373144 | E12: =($C$1-C12)/30 -> 23.9 | F12: =IF(E12<6,D12,0) -> 0 | G12: =IF(AND(E12>=6,E12<12),D12,0) -> 0 | H12: =IF(AND(E12>=12,E12<24),D12,0) -> 373144 | I12: =IF(AND(E12>=24,E12<36),D12,0) -> 0 | J12: =IF(E12>=36,D12,0) -> 0 | K12: =F12*$F$4+G12*$G$4+H12*$H$4+I12*$I$4+J12*$J$4 -> 186572
A13: Phải thu - Công Ty TNHH Hua Xin | B13: 835 | C13: 43522 | D13: 75066160 | E13: =($C$1-C13)/30 -> 22.466667 | F13: =IF(E13<6,D13,0) -> 0 | G13: =IF(AND(E13>=6,E13<12),D13,0) -> 0 | H13: =IF(AND(E13>=12,E13<24),D13,0) -> 75066160 | I13: =IF(AND(E13>=24,E13<36),D13,0) -> 0 | J13: =IF(E13>=36,D13,0) -> 0 | K13: =F13*$F$4+G13*$G$4+H13*$H$4+I13*$I$4+J13*$J$4 -> 37533080
A14: Phải thu - Công Ty TNHH Hua Xin | B14: 835 | C14: 43522 | D14: 7506616 | E14: =($C$1-C14)/30 -> 22.466667 | F14: =IF(E14<6,D14,0) -> 0 | G14: =IF(AND(E14>=6,E14<12),D14,0) -> 0 | H14: =IF(AND(E14>=12,E14<24),D14,0) -> 7506616 | I14: =IF(AND(E14>=24,E14<36),D14,0) -> 0 | J14: =IF(E14>=36,D14,0) -> 0 | K14: =F14*$F$4+G14*$G$4+H14*$H$4+I14*$I$4+J14*$J$4 -> 3753308
A15: Phải thu - Công Ty TNHH Hua Xin | B15: 0000850 | C15: 43549 | D15: 7062240 | E15: =($C$1-C15)/30 -> 21.566667 | F15: =IF(E15<6,D15,0) -> 0 | G15: =IF(AND(E15>=6,E15<12),D15,0) -> 0 | H15: =IF(AND(E15>=12,E15<24),D15,0) -> 7062240 | I15: =IF(AND(E15>=24,E15<36),D15,0) -> 0 | J15: =IF(E15>=36,D15,0) -> 0 | K15: =F15*$F$4+G15*$G$4+H15*$H$4+I15*$I$4+J15*$J$4 -> 3531120
A16: Phải thu - Công Ty TNHH Hua Xin | B16: 0000850 | C16: 43549 | D16: 706224 | E16: =($C$1-C16)/30 -> 21.566667 | F16: =IF(E16<6,D16,0) -> 0 | G16: =IF(AND(E16>=6,E16<12),D16,0) -> 0 | H16: =IF(AND(E16>=12,E16<24),D16,0) -> 706224 | I16: =IF(AND(E16>=24,E16<36),D16,0) -> 0 | J16: =IF(E16>=36,D16,0) -> 0 | K16: =F16*$F$4+G16*$G$4+H16*$H$4+I16*$I$4+J16*$J$4 -> 353112
A17: Phải thu - Công Ty TNHH Hua Xin | B17: 0 | C17: 43466 | D17: 57926880 | E17: =($C$1-C17)/30 -> 24.333333 | F17: =IF(E17<6,D17,0) -> 0 | G17: =IF(AND(E17>=6,E17<12),D17,0) -> 0 | H17: =IF(AND(E17>=12,E17<24),D17,0) -> 0 | I17: =IF(AND(E17>=24,E17<36),D17,0) -> 57926880 | J17: =IF(E17>=36,D17,0) -> 0 | K17: =F17*$F$4+G17*$G$4+H17*$H$4+I17*$I$4+J17*$J$4 -> 40548816
A18: Phải thu - Công Ty TNHH Hua Xin | B18: 0 | C18: 43466 | D18: 68322144 | E18: =($C$1-C18)/30 -> 24.333333 | F18: =IF(E18<6,D18,0) -> 0 | G18: =IF(AND(E18>=6,E18<12),D18,0) -> 0 | H18: =IF(AND(E18>=12,E18<24),D18,0) -> 0 | I18: =IF(AND(E18>=24,E18<36),D18,0) -> 68322144 | J18: =IF(E18>=36,D18,0) -> 0 | K18: =F18*$F$4+G18*$G$4+H18*$H$4+I18*$I$4+J18*$J$4 -> 47825501
A19: Phải thu - Công Ty TNHH Hua Xin | B19: 0 | C19: 43466 | D19: 312230565 | E19: =($C$1-C19)/30 -> 24.333333 | F19: =IF(E19<6,D19,0) -> 0 | G19: =IF(AND(E19>=6,E19<12),D19,0) -> 0 | H19: =IF(AND(E19>=12,E19<24),D19,0) -> 0 | I19: =IF(AND(E19>=24,E19<36),D19,0) -> 312230565 | J19: =IF(E19>=36,D19,0) -> 0 | K19: =F19*$F$4+G19*$G$4+H19*$H$4+I19*$I$4+J19*$J$4 -> 2.185614e+08
A20: Phải thu - Công Ty TNHH Hua Xin | B20: 0000900 | C20: 43581 | D20: 336311154 | E20: =($C$1-C20)/30 -> 20.5 | F20: =IF(E20<6,D20,0) -> 0 | G20: =IF(AND(E20>=6,E20<12),D20,0) -> 0 | H20: =IF(AND(E20>=12,E20<24),D20,0) -> 336311154 | I20: =IF(AND(E20>=24,E20<36),D20,0) -> 0 | J20: =IF(E20>=36,D20,0) -> 0 | K20: =F20*$F$4+G20*$G$4+H20*$H$4+I20*$I$4+J20*$J$4 -> 168155577
A21: Phải thu - Công Ty TNHH Hua Xin | B21: 0000900 | C21: 43581 | D21: 33631115 | E21: =($C$1-C21)/30 -> 20.5 | F21: =IF(E21<6,D21,0) -> 0 | G21: =IF(AND(E21>=6,E21<12),D21,0) -> 0 | H21: =IF(AND(E21>=12,E21<24),D21,0) -> 33631115 | I21: =IF(AND(E21>=24,E21<36),D21,0) -> 0 | J21: =IF(E21>=36,D21,0) -> 0 | K21: =F21*$F$4+G21*$G$4+H21*$H$4+I21*$I$4+J21*$J$4 -> 16815558
A22: Phải thu - Công Ty TNHH Hua Xin | B22: 0000960 | C22: 43614 | D22: 118888525 | E22: =($C$1-C22)/30 -> 19.4 | F22: =IF(E22<6,D22,0) -> 0 | G22: =IF(AND(E22>=6,E22<12),D22,0) -> 0 | H22: =IF(AND(E22>=12,E22<24),D22,0) -> 118888525 | I22: =IF(AND(E22>=24,E22<36),D22,0) -> 0 | J22: =IF(E22>=36,D22,0) -> 0 | K22: =F22*$F$4+G22*$G$4+H22*$H$4+I22*$I$4+J22*$J$4 -> 59444262
A23: Phải thu - Công Ty TNHH Hua Xin | B23: 0000960 | C23: 43614 | D23: 11888853 | E23: =($C$1-C23)/30 -> 19.4 | F23: =IF(E23<6,D23,0) -> 0 | G23: =IF(AND(E23>=6,E23<12),D23,0) -> 0 | H23: =IF(AND(E23>=12,E23<24),D23,0) -> 11888853 | I23: =IF(AND(E23>=24,E23<36),D23,0) -> 0 | J23: =IF(E23>=36,D23,0) -> 0 | K23: =F23*$F$4+G23*$G$4+H23*$H$4+I23*$I$4+J23*$J$4 -> 5944426.5
A24: Phải thu - Công Ty TNHH Hua Xin | B24: 57 | C24: 43675 | D24: 506710460 | E24: =($C$1-C24)/30 -> 17.366667 | F24: =IF(E24<6,D24,0) -> 0 | G24: =IF(AND(E24>=6,E24<12),D24,0) -> 0 | H24: =IF(AND(E24>=12,E24<24),D24,0) -> 506710460 | I24: =IF(AND(E24>=24,E24<36),D24,0) -> 0 | J24: =IF(E24>=36,D24,0) -> 0 | K24: =F24*$F$4+G24*$G$4+H24*$H$4+I24*$I$4+J24*$J$4 -> 253355230
A25: Phải thu - Công Ty TNHH Hua Xin | B25: 57 | C25: 43675 | D25: 50671046 | E25: =($C$1-C25)/30 -> 17.366667 | F25: =IF(E25<6,D25,0) -> 0 | G25: =IF(AND(E25>=6,E25<12),D25,0) -> 0 | H25: =IF(AND(E25>=12,E25<24),D25,0) -> 50671046 | I25: =IF(AND(E25>=24,E25<36),D25,0) -> 0 | J25: =IF(E25>=36,D25,0) -> 0 | K25: =F25*$F$4+G25*$G$4+H25*$H$4+I25*$I$4+J25*$J$4 -> 25335523
A26: Phải thu - Công Ty TNHH Hua Xin | B26: 129 | C26: 43733 | D26: 286310226 | E26: =($C$1-C26)/30 -> 15.433333 | F26: =IF(E26<6,D26,0) -> 0 | G26: =IF(AND(E26>=6,E26<12),D26,0) -> 0 | H26: =IF(AND(E26>=12,E26<24),D26,0) -> 286310226 | I26: =IF(AND(E26>=24,E26<36),D26,0) -> 0 | J26: =IF(E26>=36,D26,0) -> 0 | K26: =F26*$F$4+G26*$G$4+H26*$H$4+I26*$I$4+J26*$J$4 -> 143155113
A27: Phải thu - Công Ty TNHH Hua Xin | B27: 129 | C27: 43733 | D27: 28631023 | E27: =($C$1-C27)/30 -> 15.433333 | F27: =IF(E27<6,D27,0) -> 0 | G27: =IF(AND(E27>=6,E27<12),D27,0) -> 0 | H27: =IF(AND(E27>=12,E27<24),D27,0) -> 28631023 | I27: =IF(AND(E27>=24,E27<36),D27,0) -> 0 | J27: =IF(E27>=36,D27,0) -> 0 | K27: =F27*$F$4+G27*$G$4+H27*$H$4+I27*$I$4+J27*$J$4 -> 14315512
A28: Phải thu - Công Ty TNHH Hua Xin | B28: 162 | C28: 43764 | D28: 324885600 | E28: =($C$1-C28)/30 -> 14.4 | F28: =IF(E28<6,D28,0) -> 0 | G28: =IF(AND(E28>=6,E28<12),D28,0) -> 0 | H28: =IF(AND(E28>=12,E28<24),D28,0) -> 324885600 | I28: =IF(AND(E28>=24,E28<36),D28,0) -> 0 | J28: =IF(E28>=36,D28,0) -> 0 | K28: =F28*$F$4+G28*$G$4+H28*$H$4+I28*$I$4+J28*$J$4 -> 162442800
A29: Phải thu - Công Ty TNHH Hua Xin | B29: 162 | C29: 43764 | D29: 32488560 | E29: =($C$1-C29)/30 -> 14.4 | F29: =IF(E29<6,D29,0) -> 0 | G29: =IF(AND(E29>=6,E29<12),D29,0) -> 0 | H29: =IF(AND(E29>=12,E29<24),D29,0) -> 32488560 | I29: =IF(AND(E29>=24,E29<36),D29,0) -> 0 | J29: =IF(E29>=36,D29,0) -> 0 | K29: =F29*$F$4+G29*$G$4+H29*$H$4+I29*$I$4+J29*$J$4 -> 16244280
A30: Phải thu - Công Ty TNHH Hua Xin | B30: 206 | C30: 43796 | D30: 10468670 | E30: =($C$1-C30)/30 -> 13.333333 | F30: =IF(E30<6,D30,0) -> 0 | G30: =IF(AND(E30>=6,E30<12),D30,0) -> 0 | H30: =IF(AND(E30>=12,E30<24),D30,0) -> 10468670 | I30: =IF(AND(E30>=24,E30<36),D30,0) -> 0 | J30: =IF(E30>=36,D30,0) -> 0 | K30: =F30*$F$4+G30*$G$4+H30*$H$4+I30*$I$4+J30*$J$4 -> 5234335
A31: Phải thu - Công Ty TNHH Hua Xin | B31: 206 | C31: 43796 | D31: 1046867 | E31: =($C$1-C31)/30 -> 13.333333 | F31: =IF(E31<6,D31,0) -> 0 | G31: =IF(AND(E31>=6,E31<12),D31,0) -> 0 | H31: =IF(AND(E31>=12,E31<24),D31,0) -> 1046867 | I31: =IF(AND(E31>=24,E31<36),D31,0) -> 0 | J31: =IF(E31>=36,D31,0) -> 0 | K31: =F31*$F$4+G31*$G$4+H31*$H$4+I31*$I$4+J31*$J$4 -> 523433.5
A32: Phải thu - Công Ty TNHH Hua Xin | B32: 236 | C32: 43823 | D32: 18240710 | E32: =($C$1-C32)/30 -> 12.433333 | F32: =IF(E32<6,D32,0) -> 0 | G32: =IF(AND(E32>=6,E32<12),D32,0) -> 0 | H32: =IF(AND(E32>=12,E32<24),D32,0) -> 18240710 | I32: =IF(AND(E32>=24,E32<36),D32,0) -> 0 | J32: =IF(E32>=36,D32,0) -> 0 | K32: =F32*$F$4+G32*$G$4+H32*$H$4+I32*$I$4+J32*$J$4 -> 9120355
A33: Phải thu - Công Ty TNHH Hua Xin | B33: 236 | C33: 43823 | D33: 1824071 | E33: =($C$1-C33)/30 -> 12.433333 | F33: =IF(E33<6,D33,0) -> 0 | G33: =IF(AND(E33>=6,E33<12),D33,0) -> 0 | H33: =IF(AND(E33>=12,E33<24),D33,0) -> 1824071 | I33: =IF(AND(E33>=24,E33<36),D33,0) -> 0 | J33: =IF(E33>=36,D33,0) -> 0 | K33: =F33*$F$4+G33*$G$4+H33*$H$4+I33*$I$4+J33*$J$4 -> 912035.5
A34: Phải thu - Công Ty TNHH Hua Xin | C34: 43101 | D34: 380848114 | E34: =($C$1-C34)/30 -> 36.5 | F34: =IF(E34<6,D34,0) -> 0 | G34: =IF(AND(E34>=6,E34<12),D34,0) -> 0 | H34: =IF(AND(E34>=12,E34<24),D34,0) -> 0 | I34: =IF(AND(E34>=24,E34<36),D34,0) -> 0 | J34: =IF(E34>=36,D34,0) -> 380848114 | K34: =F34*$F$4+G34*$G$4+H34*$H$4+I34*$I$4+J34*$J$4 -> 380848114
A35: Công Ty TNHH TM Tam Hợp Phát | C35: 43678 | D35: 2299946400 | E35: =($C$1-C35)/30 -> 17.266667 | F35: =IF(E35<6,D35,0) -> 0 | G35: =IF(AND(E35>=6,E35<12),D35,0) -> 0 | H35: =IF(AND(E35>=12,E35<24),D35,0) -> 2299946400 | I35: =IF(AND(E35>=24,E35<36),D35,0) -> 0 | J35: =IF(E35>=36,D35,0) -> 0 | K35: =F35*$F$4+G35*$G$4+H35*$H$4+I35*$I$4+J35*$J$4 -> 1149973200
A36: Phải thu - Công ty Cổ Phần Trần Đức | B36: 0000564 | C36: 44119 | D36: 503591716 | E36: =($C$1-C36)/30 -> 2.5666667 | F36: =IF(E36<6,D36,0) -> 503591716 | G36: =IF(AND(E36>=6,E36<12),D36,0) -> 0 | H36: =IF(AND(E36>=12,E36<24),D36,0) -> 0 | I36: =IF(AND(E36>=24,E36<36),D36,0) -> 0 | J36: =IF(E36>=36,D36,0) -> 0 | K36: =F36*$F$4+G36*$G$4+H36*$H$4+I36*$I$4+J36*$J$4 -> 0
A37: Phải thu - Công ty Cổ Phần Trần Đức | B37: 0000568 | C37: 44130 | D37: 346001630 | E37: =($C$1-C37)/30 -> 2.2 | F37: =IF(E37<6,D37,0) -> 346001630 | G37: =IF(AND(E37>=6,E37<12),D37,0) -> 0 | H37: =IF(AND(E37>=12,E37<24),D37,0) -> 0 | I37: =IF(AND(E37>=24,E37<36),D37,0) -> 0 | J37: =IF(E37>=36,D37,0) -> 0 | K37: =F37*$F$4+G37*$G$4+H37*$H$4+I37*$I$4+J37*$J$4 -> 0
A38: Phải thu - Công ty Cổ Phần Trần Đức | B38: 0000568 | C38: 44130 | D38: 34600163 | E38: =($C$1-C38)/30 -> 2.2 | F38: =IF(E38<6,D38,0) -> 34600163 | G38: =IF(AND(E38>=6,E38<12),D38,0) -> 0 | H38: =IF(AND(E38>=12,E38<24),D38,0) -> 0 | I38: =IF(AND(E38>=24,E38<36),D38,0) -> 0 | J38: =IF(E38>=36,D38,0) -> 0 | K38: =F38*$F$4+G38*$G$4+H38*$H$4+I38*$I$4+J38*$J$4 -> 0
A39: Phải thu - Công ty Cổ Phần Trần Đức | B39: 0000009 | C39: 44160 | D39: 21292050 | E39: =($C$1-C39)/30 -> 1.2 | F39: =IF(E39<6,D39,0) -> 21292050 | G39: =IF(AND(E39>=6,E39<12),D39,0) -> 0 | H39: =IF(AND(E39>=12,E39<24),D39,0) -> 0 | I39: =IF(AND(E39>=24,E39<36),D39,0) -> 0 | J39: =IF(E39>=36,D39,0) -> 0 | K39: =F39*$F$4+G39*$G$4+H39*$H$4+I39*$I$4+J39*$J$4 -> 0
A40: Phải thu - Công ty Cổ Phần Trần Đức | B40: 0000009 | C40: 44160 | D40: 2129205 | E40: =($C$1-C40)/30 -> 1.2 | F40: =IF(E40<6,D40,0) -> 2129205 | G40: =IF(AND(E40>=6,E40<12),D40,0) -> 0 | H40: =IF(AND(E40>=12,E40<24),D40,0) -> 0 | I40: =IF(AND(E40>=24,E40<36),D40,0) -> 0 | J40: =IF(E40>=36,D40,0) -> 0 | K40: =F40*$F$4+G40*$G$4+H40*$H$4+I40*$I$4+J40*$J$4 -> 0
...

Sheet CN
A1: 42947 | B1: 0000188 | C1: Poly trang trí - Công ty TNHH nội thất gỗ Phú Đỉnh | D1: 5111 | E1: 19213770 | G1: treo nợ
A2: 42947 | B2: 0000188 | C2: VAT đầu ra - Công ty TNHH nội thất gỗ Phú Đỉnh | D2: 33311 | E2: 1921377 | F2: =+E2+E1 -> 21135147
A3: 43069 | B3: 0 | C3: Phải thu - Công ty TNHH nội thất gỗ Phú Đỉnh | D3: 1121IVB | E3: 0 | F3: 11498772 | G3: =+E1+E2-F3 -> 9636375
G4: 55618.5 | H4: thiếu phí TT | I4: hd 313 10/2017
A5: 415 | B5: 43130 | C5: Poly trang trí - Công ty TNHH nội thất gỗ Phú Đỉnh | D5: 5111 | E5: 27421380 | G5: =+E5+E6 -> 30163518
A6: 415 | B6: 43130 | C6: VAT đầu ra - Công ty TNHH nội thất gỗ Phú Đỉnh | D6: 33311 | E6: 2742138
G7: 53394 | H7: thiếu phí TT | I7: hd 378 5/5/20
G8: 53399 | H8: thiếu phí TT | I8: hd 24/08/20
G10: =+G4+G7+G8 -> 162411.5
B11: 0000077 | C11: DT Bán poly-HD 77-18/01/21-Cty Phú Đỉnh | D11: 5112 | E11: 3575520 | F11: =+E11+E12 -> 3933072 | G11: =+F11 -> 3933072
B12: 0000077 | C12: Thuế GTGT đầu ra HĐ: 0000077,18/01/21 | D12: 33311 | E12: 357552
G13: =+G11+G5+G3 -> 43732965
A16: 42947 | B16: 0000188 | C16: Poly trang trí - Công ty TNHH nội thất gỗ Phú Đỉnh | D16: 5111 | E16: 19213770 | G16: treo nợ đến hiện tại
A17: 42947 | B17: 0000188 | C17: VAT đầu ra - Công ty TNHH nội thất gỗ Phú Đỉnh | D17: 33311 | E17: 1921377 | F17: =+E17+E16 -> 21135147
A18: 43069 | B18: 0 | C18: Phải thu - Công ty TNHH nội thất gỗ Phú Đỉnh | D18: 1121IVB | E18: 0 | F18: 11498772 | G18: =+E16+E17-F18 -> 9636375
A20: 415 | B20: 43130 | C20: Poly trang trí - Công ty TNHH nội thất gỗ Phú Đỉnh | D20: 5111 | E20: 27421380 | G20: =+E20+E21 -> 30163518
A21: 415 | B21: 43130 | C21: VAT đầu ra - Công ty TNHH nội thất gỗ Phú Đỉnh | D21: 33311 | E21: 2742138 | H21: 39799893
B23: 0000077 | C23: DT Bán poly-HD 77-18/01/21-Cty Phú Đỉnh | D23: 5112 | E23: 3575520 | F23: =+E23+E24 -> 3933072 | G23: =+F23 -> 3933072
B24: 0000077 | C24: Thuế GTGT đầu ra HĐ: 0000077,18/01/21 | D24: 33311 | E24: 357552 | G24: =SUM(G18:G23) -> 43732965
A28: 70 | B28: 44722 | C28: Chi phí Dầu DO, Xăng Ron E5-HĐ 70-10/06/22-CTY An Khánh Phát | D28: 6417 | G28: 7293236
A29: 70 | B29: 44722 | C29: Chi phí Dầu DO, Xăng Ron E5-HĐ 70-10/06/22-CTY An Khánh Phát | D29: 6427 | G29: 1099273
A30: 70 | B30: 44722 | C30: Thuế GTGT mua vào HĐ số :70,10/06/22 | D30: 1331 | G30: 839251
G31: =SUM(G28:G30) -> 9231760
C34: Diễn giải | D34: TK | E34: VND
A35: Ngày | B35: Số Hđ | D35: DU | E35: Nợ | F35: Có
C36: SỐ DƯ ĐẦU KỲ | D36: 0 | E36: 519590653 | F36: 0
A37: 44222 | B37: 0000085 | C37: DT Bán poly-HD 85-26/01/21-Cty Siêu Nghệ | D37: 5112 | E37: 221116661 | F37: 0
A38: 44222 | B38: 0000085 | C38: Thuế GTGT đầu ra HĐ: 0000085,26/01/21 | D38: 33311 | E38: 22111666 | F38: 0
A39: 44231 | B39: 0000585 | C39: Cty Siêu Nghệ thanh toán tiền HD 585 | D39: 1121IVB | E39: 0 | F39: 72677671
A40: 44254 | B40: 0000127 | C40: DT Bán poly HD 127-27/02/21-Cty Siêu NGhệ | D40: 5112 | E40: 131162922 | F40: 0
A41: 44254 | B41: 0000127 | C41: Thuế GTGT đầu ra HĐ: 0000127,27/02/21 | D41: 33311 | E41: 13116292 | F41: 0
A42: 44267 | B42: 0000033 | C42: Công Ty Siêu Nghệ thanh toán tiền 1 phần HĐ 33 | D42: 1121IVB | E42: 0 | F42: 99972500
A43: 44286 | B43: 0000161 | C43: DT Bán poly trang trí HĐ 161-31/03/21-Cty Siêu Nghệ | D43: 5112 | E43: 279488246 | F43: 0
A44: 44286 | B44: 0000161 | C44: Thuế GTGT đầu ra HĐ: 0000161,31/03/21 | D44: 33311 | E44: 27948825 | F44: 0 | I44: =+E40+E41+E43+E44 -> 451716285 | J44: 300000000 | K44: =+I44-J44 -> 151716285 | L44: 127+161 | M44: 44589 | N44: CTY Siêu Nghệ thanh toán tiền hàng T2+1 phần T3/21-HĐ 127+161
A45: 44287 | C45: Công Ty Siêu Nghệ Thanh toán phần còn lại hóa đơn 33 và 1 phần hóa đơn 66/t12 2020 | D45: 1121IVB | E45: 0 | F45: 175000000
A46: 44306 | B46: 33+66 | C46: Công Ty Siêu Nghệ Thanh Toán Tiền HĐ 33+66 | D46: 1121IVB | E46: 0 | F46: 171912982
A47: 44306 | C47: Phí ngân hàng | D47: 6427 | E47: 0 | F47: 27500
A48: 44315 | B48: 0000187 | C48: DT Bán poly trang trí HĐ 187-29/04/21-Cty Siêu NGhệ | D48: 5112 | E48: 295822872 | F48: 0
A49: 44315 | B49: 0000187 | C49: Thuế GTGT đầu ra HĐ: 0000187,29/04/21 | D49: 33311 | E49: 29582287 | F49: 0 | I49: =+K44+E48+E49 -> 477121444 | J49: 200000000 | K49: =+I49-J49 -> 277121444 | L49: 161+187 | M49: 44677 | N49: DT Bán poly trang trí HĐ 161(31/03/21)+187(29/04/21)-CTY Siêu Nghệ
I50: =+K49 -> 277121444 | J50: 50000000 | K50: =+I50-J50 -> 227121444 | L50: 187 | M50: 44869 | N50: CTYTNHH SIÊU NGHỆ thanh tiếp 1 phần tiền hàng T4/21 HD 187 (29/04/21)
...
